Workbook

Sheet Assumptions
A1: UNIVERSIDAD DE MONDRAGÓN - ASSUMPTIONS
A3: GROWTH ASSUMPTIONS
A4: Item | B4: FY 2025 | C4: FY 2026 | D4: FY 2027 | E4: FY 2028 | F4: FY 2029
A5: Revenue growth rate (%) | B5: 0.08 | C5: 0.075 | D5: 0.07 | E5: 0.065 | F5: 0.06
A6: Online expansion students | B6: 60 | C6: 80 | D6: 80 | E6: 80 | F6: 80
A7: Revenue per online student (€) | B7: 4000 | C7: 4200 | D7: 4400 | E7: 4600 | F7: 4800
A8: International students (%) | B8: 0.02 | C8: 0.04 | D8: 0.06 | E8: 0.08 | F8: 0.1
A9: International premium (%) | B9: 0.15 | C9: 0.15 | D9: 0.15 | E9: 0.15 | F9: 0.15
A10: Corporate B2B revenue (€) | B10: 250000 | C10: 500000 | D10: 750000 | E10: 1000000 | F10: 1200000
A12: OPERATING ASSUMPTIONS
A13: Item | B13: FY 2025 | C13: FY 2026 | D13: FY 2027 | E13: FY 2028 | F13: FY 2029
A14: COGS / Sales (%) | B14: 0.002 | C14: 0.0019 | D14: 0.0018 | E14: 0.0018 | F14: 0.0017
A15: Other income / Sales (%) | B15: 0.182 | C15: 0.175 | D15: 0.17 | E15: 0.165 | F15: 0.16
A16: SG&A / Sales (%) | B16: 1.12 | C16: 1.07 | D16: 1.03 | E16: 1 | F16: 0.98
A17: D&A / Sales (%) | B17: 0.007 | C17: 0.007 | D17: 0.006 | E17: 0.006 | F17: 0.006
A19: BALANCE SHEET ASSUMPTIONS
A20: Item | B20: FY 2025 | C20: FY 2026 | D20: FY 2027 | E20: FY 2028 | F20: FY 2029
A21: DSO (days) | B21: 68 | C21: 65 | D21: 63 | E21: 60 | F21: 60
A22: DPO (days) | B22: 56 | C22: 55 | D22: 54 | E22: 53 | F22: 52
A23: CAPEX / Sales (%) | B23: 0.025 | C23: 0.023 | D23: 0.02 | E23: 0.018 | F23: 0.018
A24: Tax rate (%) | B24: 0.24 | C24: 0.24 | D24: 0.24 | E24: 0.24 | F24: 0.24
A26: DCF ASSUMPTIONS
A27: Risk-free rate (%) | B27: 0.032
A28: Market risk premium (%) | B28: 0.0694
A29: Beta | B29: 1.25
A30: Cost of Equity (%) | B30: =(B27+B28*B29) -> 0.11875
A31: Terminal growth rate (%) | B31: 0.025
A34: HISTORICAL DATA (FY 2024)
A35: Revenue | B35: 19599359
A36: EBITDA | B36: 88799
A37: D&A | B37: 133762
A38: EBIT | B38: -44963

Sheet IS
A1: INCOME STATEMENT
A3: Item | B3: FY 2024 | C3: FY 2025 | D3: FY 2026 | E3: FY 2027 | F3: FY 2028 | G3: FY 2029
A4: Base revenue | B4: 19599359 | C4: =B4*(1+Assumptions!B5) -> 21167308 | D4: =C4*(1+Assumptions!C5) -> 22754856 | E4: =D4*(1+Assumptions!D5) -> 24347696 | F4: =E4*(1+Assumptions!E5) -> 25930296 | G4: =F4*(1+Assumptions!F5) -> 27486114
A5: + Online expansion | B5: 0 | C5: =Assumptions!B6*Assumptions!B7 -> 240000 | D5: =Assumptions!C6*Assumptions!C7 -> 336000 | E5: =Assumptions!D6*Assumptions!D7 -> 352000 | F5: =Assumptions!E6*Assumptions!E7 -> 368000 | G5: =Assumptions!F6*Assumptions!F7 -> 384000
A6: + International premium | B6: 0 | C6: =C4*Assumptions!B8*Assumptions!B9 -> 63501.923 | D6: =D4*Assumptions!C8*Assumptions!C9 -> 136529.13 | E6: =E4*Assumptions!D8*Assumptions!D9 -> 219129.26 | F6: =F4*Assumptions!E8*Assumptions!E9 -> 311163.55 | G6: =G4*Assumptions!F8*Assumptions!F9 -> 412291.71
A7: + Corporate B2B | B7: 0 | C7: =Assumptions!B10 -> 250000 | D7: =Assumptions!C10 -> 500000 | E7: =Assumptions!D10 -> 750000 | F7: =Assumptions!E10 -> 1000000 | G7: =Assumptions!F10 -> 1200000
A8: TOTAL REVENUE | B8: =SUM(B4:B7) -> 19599359 | C8: =SUM(C4:C7) -> 21720810 | D8: =SUM(D4:D7) -> 23727385 | E8: =SUM(E4:E7) -> 25668825 | F8: =SUM(F4:F7) -> 27609459 | G8: =SUM(G4:G7) -> 29482405
A9: YoY Growth (%) | C9: =C8/B8-1 -> 0.10824082 | D9: =D8/C8-1 -> 0.092380317 | E9: =E8/D8-1 -> 0.081822756 | F9: =F8/E8-1 -> 0.075602779 | G9: =G8/F8-1 -> 0.067837109
A11: COGS | B11: -39703 | C11: =-C8*Assumptions!B14 -> -43441.619 | D11: =-D8*Assumptions!C14 -> -45082.031 | E11: =-E8*Assumptions!D14 -> -46203.885 | F11: =-F8*Assumptions!E14 -> -49697.027 | G11: =-G8*Assumptions!F14 -> -50120.089
A12: GROSS PROFIT | B12: =B8+B11 -> 19559656 | C12: =C8+C11 -> 21677368 | D12: =D8+D11 -> 23682303 | E12: =E8+E11 -> 25622621 | F12: =F8+F11 -> 27559762 | G12: =G8+G11 -> 29432285
A13: Gross Margin (%) | B13: =B12/B8 -> 0.99797427 | C13: =C12/C8 -> 0.998 | D13: =D12/D8 -> 0.9981 | E13: =E12/E8 -> 0.9982 | F13: =F12/F8 -> 0.9982 | G13: =G12/G8 -> 0.9983
A15: Other income | B15: 3576770 | C15: =C8*Assumptions!B15 -> 3953187.4 | D15: =D8*Assumptions!C15 -> 4152292.4 | E15: =E8*Assumptions!D15 -> 4363700.2 | F15: =F8*Assumptions!E15 -> 4555560.8 | G15: =G8*Assumptions!F15 -> 4717184.9
A16: SG&A | B16: -23047627 | C16: =-C8*Assumptions!B16 -> -24327307 | D16: =-D8*Assumptions!C16 -> -25388302 | E16: =-E8*Assumptions!D16 -> -26438890 | F16: =-F8*Assumptions!E16 -> -27609459 | G16: =-G8*Assumptions!F16 -> -28892757
A17: EBITDA | B17: =B12+B15+B16 -> 88799 | C17: =C12+C15+C16 -> 1303248.6 | D17: =D12+D15+D16 -> 2446293.4 | E17: =E12+E15+E16 -> 3547431.6 | F17: =F12+F15+F16 -> 4505863.8 | G17: =G12+G15+G16 -> 5256712.9
A18: EBITDA Margin (%) | B18: =B17/B8 -> 0.0045307094 | C18: =C17/C8 -> 0.06 | D18: =D17/D8 -> 0.1031 | E18: =E17/E8 -> 0.1382 | F18: =F17/F8 -> 0.1632 | G18: =G17/G8 -> 0.1783
A20: D&A | B20: -133762 | C20: =-C8*Assumptions!B17 -> -152045.67 | D20: =-D8*Assumptions!C17 -> -166091.69 | E20: =-E8*Assumptions!D17 -> -154012.95 | F20: =-F8*Assumptions!E17 -> -165656.76 | G20: =-G8*Assumptions!F17 -> -176894.43
A21: EBIT | B21: =B17+B20 -> -44963 | C21: =C17+C20 -> 1151202.9 | D21: =D17+D20 -> 2280201.7 | E21: =E17+E20 -> 3393418.7 | F21: =F17+F20 -> 4340207 | G21: =G17+G20 -> 5079818.4
A22: EBIT Margin (%) | B22: =B21/B8 -> -0.0022941056 | C22: =C21/C8 -> 0.053 | D22: =D21/D8 -> 0.0961 | E22: =E21/E8 -> 0.1322 | F22: =F21/F8 -> 0.1572 | G22: =G21/G8 -> 0.1723
A24: Financial income | B24: 235683 | C24: =C8*0.012 -> 260649.72 | D24: =D8*0.012 -> 284728.62 | E24: =E8*0.012 -> 308025.9 | F24: =F8*0.012 -> 331313.51 | G24: =G8*0.012 -> 353788.86
A25: Financial expense | B25: 0 | C25: 0 | D25: 0 | E25: 0 | F25: 0 | G25: 0
A26: EBT | B26: =B21+B24+B25 -> 190720 | C26: =C21+C24+C25 -> 1411852.6 | D26: =D21+D24+D25 -> 2564930.3 | E26: =E21+E24+E25 -> 3701444.6 | F26: =F21+F24+F25 -> 4671520.5 | G26: =G21+G24+G25 -> 5433607.3
A27: Tax | B27: 0 | C27: =-C26*Assumptions!B24 -> -338844.63 | D27: =-D26*Assumptions!C24 -> -615583.27 | E27: =-E26*Assumptions!D24 -> -888346.69 | F27: =-F26*Assumptions!E24 -> -1121164.9 | G27: =-G26*Assumptions!F24 -> -1304065.8
A28: NET INCOME | B28: =B26+B27 -> 190720 | C28: =C26+C27 -> 1073008 | D28: =D26+D27 -> 1949347 | E28: =E26+E27 -> 2813097.9 | F28: =F26+F27 -> 3550355.6 | G28: =G26+G27 -> 4129541.6
A29: Net Margin (%) | B29: =B28/B8 -> 0.0097309305 | C29: =C28/C8 -> 0.0494 | D29: =D28/D8 -> 0.082156 | E29: =E28/E8 -> 0.109592 | F29: =F28/F8 -> 0.128592 | G29: =G28/G8 -> 0.140068

Sheet BS
A1: BALANCE SHEET
A3: Item | B3: FY 2024 | C3: FY 2025 | D3: FY 2026 | E3: FY 2027 | F3: FY 2028 | G3: FY 2029
A4: PP&E | B4: 1039342 | C4: =B4+IS!C8*Assumptions!B23 + IS!C20 -> 1430316.6 | D4: =C4+IS!D8*Assumptions!C23 + IS!D20 -> 1809954.7 | E4: =D4+IS!E8*Assumptions!D23 + IS!E20 -> 2169318.3 | F4: =E4+IS!F8*Assumptions!E23 + IS!F20 -> 2500631.8 | G4: =F4+IS!G8*Assumptions!F23 + IS!G20 -> 2854420.7
A5: Other non-current assets | B5: 4383541 | C5: 4570000 | D5: 4750000 | E5: 4930000 | F5: 5110000 | G5: 5290000
A6: TOTAL NON-CURRENT ASSETS | B6: =B4+B5 -> 5422883 | C6: =C4+C5 -> 6000316.6 | D6: =D4+D5 -> 6559954.7 | E6: =E4+E5 -> 7099318.3 | F6: =F4+F5 -> 7610631.8 | G6: =G4+G5 -> 8144420.7
A8: Accounts receivable | B8: 3625643 | C8: =IS!C8*Assumptions!B21/365 -> 4046616.6 | D8: =IS!D8*Assumptions!C21/365 -> 4225424.7 | E8: =IS!E8*Assumptions!D21/365 -> 4430509.5 | F8: =IS!F8*Assumptions!E21/365 -> 4538541.3 | G8: =IS!G8*Assumptions!F21/365 -> 4846422.8
A9: Other current assets | B9: 6435671 | C9: 6700000 | D9: 6980000 | E9: 7260000 | F9: 7540000 | G9: 7820000
A10: Cash | B10: 3638180 | C10: =B10+CF!B20 -> 3991531.6 | D10: =C10+CF!C20 -> 5450284 | E10: =D10+CF!D20 -> 7746153.7 | F10: =E10+CF!E20 -> 10893629 | G10: =F10+CF!F20 -> 14377689
A11: TOTAL CURRENT ASSETS | B11: =B8+B9+B10 -> 13699494 | C11: =C8+C9+C10 -> 14738148 | D11: =D8+D9+D10 -> 16655709 | E11: =E8+E9+E10 -> 19436663 | F11: =F8+F9+F10 -> 22972171 | G11: =G8+G9+G10 -> 27044112
A13: TOTAL ASSETS | B13: =B6+B11 -> 19122377 | C13: =C6+C11 -> 20738465 | D13: =D6+D11 -> 23215663 | E13: =E6+E11 -> 26535981 | F13: =F6+F11 -> 30582802 | G13: =G6+G11 -> 35188532
A15: Cash (reference) | B15: =B10 -> 3638180 | C15: =C10 -> 3991531.6 | D15: =D10 -> 5450284 | E15: =E10 -> 7746153.7 | F15: =F10 -> 10893629 | G15: =G10 -> 14377689
A17: EQUITY | B17: 8922949 | C17: =B17+IS!C28 -> 9995957 | D17: =C17+IS!D28 -> 11945304 | E17: =D17+IS!E28 -> 14758402 | F17: =E17+IS!F28 -> 18308758 | G17: =F17+IS!G28 -> 22438299
A19: Non-current liabilities | B19: 102136 | C19: 110000 | D19: 115000 | E19: 120000 | F19: 125000 | G19: 130000
A21: Accounts payable | B21: 3018016 | C21: =IS!C8*Assumptions!B22/365 -> 3332507.8 | D21: =IS!D8*Assumptions!C22/365 -> 3575359.4 | E21: =IS!E8*Assumptions!D22/365 -> 3797579.6 | F21: =IS!F8*Assumptions!E22/365 -> 4009044.8 | G21: =IS!G8*Assumptions!F22/365 -> 4200233.1
A22: Other current liabilities | B22: 7079276 | C22: 7300000 | D22: 7580000 | E22: 7860000 | F22: 8140000 | G22: 8420000
A23: TOTAL CURRENT LIABILITIES | B23: =B21+B22 -> 10097292 | C23: =C21+C22 -> 10632508 | D23: =D21+D22 -> 11155359 | E23: =E21+E22 -> 11657580 | F23: =F21+F22 -> 12149045 | G23: =G21+G22 -> 12620233
A25: TOTAL LIABILITIES | B25: =B19+B23 -> 10199428 | C25: =C19+C23 -> 10742508 | D25: =D19+D23 -> 11270359 | E25: =E19+E23 -> 11777580 | F25: =F19+F23 -> 12274045 | G25: =G19+G23 -> 12750233
A27: TOTAL L&E | B27: =B17+B25 -> 19122377 | C27: =C17+C25 -> 20738465 | D27: =D17+D25 -> 23215663 | E27: =E17+E25 -> 26535981 | F27: =F17+F25 -> 30582802 | G27: =G17+G25 -> 35188532
A29: CHECK (must be 0) | B29: =B13-B27 -> 0 | C29: =C13-C27 -> 0 | D29: =D13-D27 -> 0 | E29: =E13-E27 -> 0 | F29: =F13-F27 -> 0 | G29: =G13-G27 -> 0

Sheet CF
A1: CASH FLOW STATEMENT
A3: Item | B3: FY 2025 | C3: FY 2026 | D3: FY 2027 | E3: FY 2028 | F3: FY 2029
A4: OPERATING CF
A5: Net Income | B5: =IS!C28 -> 1073008 | C5: =IS!D28 -> 1949347 | D5: =IS!E28 -> 2813097.9 | E5: =IS!F28 -> 3550355.6 | F5: =IS!G28 -> 4129541.6
A6: + D&A | B6: =-IS!C20 -> 152045.67 | C6: =-IS!D20 -> 166091.69 | D6: =-IS!E20 -> 154012.95 | E6: =-IS!F20 -> 165656.76 | F6: =-IS!G20 -> 176894.43
A7: Change in AR | B7: =-(BS!C8-BS!B8) -> -420973.59 | C7: =-(BS!D8-BS!C8) -> -178808.12 | D7: =-(BS!E8-BS!D8) -> -205084.8 | E7: =-(BS!F8-BS!E8) -> -108031.77 | F7: =-(BS!G8-BS!F8) -> -307881.52
A8: Change in AP | B8: =BS!C21-BS!B21 -> 314491.78 | C8: =BS!D21-BS!C21 -> 242851.59 | D8: =BS!E21-BS!D21 -> 222220.21 | E8: =BS!F21-BS!E21 -> 211465.22 | F8: =BS!G21-BS!F21 -> 191188.3
A9: Other WC changes | B9: =-(BS!C9-BS!B9)+(BS!C22-BS!B22) -> -43605 | C9: =-(BS!D9-BS!C9)+(BS!D22-BS!C22) -> 0 | D9: =-(BS!E9-BS!D9)+(BS!E22-BS!D22) -> 0 | E9: =-(BS!F9-BS!E9)+(BS!F22-BS!E22) -> 0 | F9: =-(BS!G9-BS!F9)+(BS!G22-BS!F22) -> 0
A10: Operating CF | B10: =SUM(B5:B9) -> 1074966.9 | C10: =SUM(C5:C9) -> 2179482.2 | D10: =SUM(D5:D9) -> 2984246.2 | E10: =SUM(E5:E9) -> 3819445.8 | F10: =SUM(F5:F9) -> 4189742.8
A12: INVESTING CF
A13: CAPEX | B13: =-(BS!C4-BS!B4-IS!C20) -> -543020.24 | C13: =-(BS!D4-BS!C4-IS!D20) -> -545729.85 | D13: =-(BS!E4-BS!D4-IS!E20) -> -513376.5 | E13: =-(BS!F4-BS!E4-IS!F20) -> -496970.27 | F13: =-(BS!G4-BS!F4-IS!G20) -> -530683.3
A14: Change in other non-current assets | B14: =-(BS!C5-BS!B5) -> -186459 | C14: =-(BS!D5-BS!C5) -> -180000 | D14: =-(BS!E5-BS!D5) -> -180000 | E14: =-(BS!F5-BS!E5) -> -180000 | F14: =-(BS!G5-BS!F5) -> -180000
A15: Investing CF | B15: =B13+B14 -> -729479.24 | C15: =C13+C14 -> -725729.85 | D15: =D13+D14 -> -693376.5 | E15: =E13+E14 -> -676970.27 | F15: =F13+F14 -> -710683.3
A17: FINANCING CF
A18: Change in debt | B18: =BS!C19-BS!B19 -> 7864 | C18: =BS!D19-BS!C19 -> 5000 | D18: =BS!E19-BS!D19 -> 5000 | E18: =BS!F19-BS!E19 -> 5000 | F18: =BS!G19-BS!F19 -> 5000
A19: Financing CF | B19: =B18 -> 7864 | C19: =C18 -> 5000 | D19: =D18 -> 5000 | E19: =E18 -> 5000 | F19: =F18 -> 5000
B20: =B21 -> 353351.61 | C20: =C21 -> 1458752.3 | D20: =D21 -> 2295869.7 | E20: =E21 -> 3147475.5 | F20: =F21 -> 3484059.5
A21: NET CHANGE IN CASH | B21: =B10+B15+B19 -> 353351.61 | C21: =C10+C15+C19 -> 1458752.3 | D21: =D10+D15+D19 -> 2295869.7 | E21: =E10+E15+E19 -> 3147475.5 | F21: =F10+F15+F19 -> 3484059.5
A23: CHECK (must be 0) | B23: =B21-(BS!C10-BS!B10) -> 0 | C23: =C21-(BS!D10-BS!C10) -> 0 | D23: =D21-(BS!E10-BS!D10) -> 0 | E23: =E21-(BS!F10-BS!E10) -> 0 | F23: =F21-(BS!G10-BS!F10) -> 0

Sheet DCF
A1: DCF VALUATION
A3: Item | B3: FY 2025 | C3: FY 2026 | D3: FY 2027 | E3: FY 2028 | F3: FY 2029
A5: EBIT | B5: =IS!C21 -> 1151202.9 | C5: =IS!D21 -> 2280201.7 | D5: =IS!E21 -> 3393418.7 | E5: =IS!F21 -> 4340207 | F5: =IS!G21 -> 5079818.4
A6: Tax (24%) | B6: =-B5*0.24 -> -276288.7 | C6: =-C5*0.24 -> -547248.41 | D6: =-D5*0.24 -> -814420.48 | E6: =-E5*0.24 -> -1041649.7 | F6: =-F5*0.24 -> -1219156.4
A7: NOPAT | B7: =B5+B6 -> 874914.21 | C7: =C5+C6 -> 1732953.3 | D7: =D5+D6 -> 2578998.2 | E7: =E5+E6 -> 3298557.3 | F7: =F5+F6 -> 3860662
A8: + D&A | B8: =-IS!C20 -> 152045.67 | C8: =-IS!D20 -> 166091.69 | D8: =-IS!E20 -> 154012.95 | E8: =-IS!F20 -> 165656.76 | F8: =-IS!G20 -> 176894.43
A9: - CAPEX | B9: =CF!B13 -> -543020.24 | C9: =CF!C13 -> -545729.85 | D9: =CF!D13 -> -513376.5 | E9: =CF!E13 -> -496970.27 | F9: =CF!F13 -> -530683.3
A10: - Change in NWC | B10: =-(CF!B7+CF!B8+CF!B9) -> 150086.81 | C10: =-(CF!C7+CF!C8+CF!C9) -> -64043.47 | D10: =-(CF!D7+CF!D8+CF!D9) -> -17135.41 | E10: =-(CF!E7+CF!E8+CF!E9) -> -103433.45 | F10: =-(CF!F7+CF!F8+CF!F9) -> 116693.22
A11: FREE CASH FLOW | B11: =B7+B8+B9+B10 -> 634026.45 | C11: =C7+C8+C9+C10 -> 1289271.7 | D11: =D7+D8+D9+D10 -> 2202499.2 | E11: =E7+E8+E9+E10 -> 2863810.4 | F11: =F7+F8+F9+F10 -> 3623566.4
A13: WACC | B13: =Assumptions!B30 -> 0.11875 | C13: =Assumptions!B30 -> 0.11875 | D13: =Assumptions!B30 -> 0.11875 | E13: =Assumptions!B30 -> 0.11875 | F13: =Assumptions!B30 -> 0.11875
A14: Discount factor | B14: =1/(1+B13)^1 -> 0.89385475 | C14: =1/(1+C13)^2 -> 0.79897631 | D14: =1/(1+D13)^3 -> 0.71416877 | E14: =1/(1+E13)^4 -> 0.63836315 | F14: =1/(1+F13)^5 -> 0.57060393
A15: PV of FCF | B15: =B11*B14 -> 566727.55 | C15: =C11*C14 -> 1030097.5 | D15: =D11*D14 -> 1572956.2 | E15: =E11*E14 -> 1828151 | F15: =F11*F14 -> 2067621.2
A17: TERMINAL VALUE
A18: Terminal FCF | F18: =F11 -> 3623566.4
A19: Terminal growth rate | F19: =Assumptions!B31 -> 0.025
A20: Terminal Value (g) | F20: =F18*(1+F19)/(F13-F19) -> 39617659
A21: PV of Terminal Value (g) | F21: =F20*F14 -> 22605992
A22: Terminal Value (Exit Multiple) | F22: =IS!G17 * 8.5 -> 44682059
A23: PV of Terminal Value (Exit Multiple) | F23: =F22*F14 -> 25495759
A26: VALUATION
A27: Sum of PV of FCF | B27: =SUM(B15:F15) -> 7065553.4
A28: PV of Terminal Value | B28: =F23 -> 25495759
A29: ENTERPRISE VALUE | B29: =B27+B28 -> 32561312
A31: (-) Net debt | B31: =BS!B19-(BS!B10) -> -3536044
A33: EQUITY VALUE | B33: =B29-B31 -> 36097356
B36: SENSITIVITY ANALYSIS: ENTERPRISE VALUE (€M)
B37: Terminal Growth Rate (g) vs WACC
B39: WACC ↓ / g → | C39: 1.5% | D39: 2.0% | E39: 2.5% | F39: 3.0% | G39: 3.5%
B40: =B41-0.005 -> 0.10875 | C40: =($F$11*(1+0.015)/($B$40-0.015))/((1+$B$40)^5)+$B$27 -> 30478864 | D40: =($F$11*(1+0.02)/($B$40-0.02))/((1+$B$40)^5)+$B$27 -> 31919758 | E40: =($F$11*(1+0.025)/($B$40-0.025))/((1+$B$40)^5)+$B$27 -> 33532699 | F40: =($F$11*(1+0.03)/($B$40-0.03))/((1+$B$40)^5)+$B$27 -> 35350458 | G40: =(F11*(1+0.035)/(0.085-0.035))/((1+0.085)^5)+B27 -> 56949164
B41: =B42-0.005 -> 0.11375 | C41: =($F$11*(1+0.015)/($B$41-0.015))/((1+$B$41)^5)+$B$27 -> 28798898 | D41: =($F$11*(1+0.02)/($B$41-0.02))/((1+$B$41)^5)+$B$27 -> 30070781 | E41: =($F$11*(1+0.025)/($B$41-0.025))/((1+$B$41)^5)+$B$27 -> 31485974 | F41: =($F$11*(1+0.03)/($B$41-0.03))/((1+$B$41)^5)+$B$27 -> 33070146 | G41: =(F11*(1+0.035)/(0.09-0.035))/((1+0.09)^5)+B27 -> 51383680
B42: =Assumptions!B30 -> 0.11875 | C42: =($F$11*(1+0.015)/($B$42-0.015))/((1+$B$42)^5)+$B$27 -> 27293366 | D42: =($F$11*(1+0.02)/($B$42-0.02))/((1+$B$42)^5)+$B$27 -> 28422249 | E42: =($F$11*(1+0.025)/($B$42-0.025))/((1+$B$42)^5)+$B$27 -> 29671545 | F42: =($F$11*(1+0.03)/($B$42-0.03))/((1+$B$42)^5)+$B$27 -> 31061608 | G42: =(F11*(1+0.035)/(0.0945-0.035))/((1+0.0945)^5)+B27 -> 47196627
B43: =B42+0.005 -> 0.12375 | C43: =($F$11*(1+0.015)/($B$43-0.015))/((1+$B$43)^5)+$B$27 -> 25937838 | D43: =($F$11*(1+0.02)/($B$43-0.02))/((1+$B$43)^5)+$B$27 -> 26944793 | E43: =($F$11*(1+0.025)/($B$43-0.025))/((1+$B$43)^5)+$B$27 -> 28053718 | F43: =($F$11*(1+0.03)/($B$43-0.03))/((1+$B$43)^5)+$B$27 -> 29280928 | G43: =(F11*(1+0.035)/(0.1-0.035))/((1+0.1)^5)+B27 -> 42891674
B44: =B43+0.005 -> 0.12875 | C44: =($F$11*(1+0.015)/($B$44-0.015))/((1+$B$44)^5)+$B$27 -> 24712194 | D44: =($F$11*(1+0.02)/($B$44-0.02))/((1+$B$44)^5)+$B$27 -> 25614460 | E44: =($F$11*(1+0.025)/($B$44-0.025))/((1+$B$44)^5)+$B$27 -> 26603691 | F44: =($F$11*(1+0.03)/($B$44-0.03))/((1+$B$44)^5)+$B$27 -> 27693098 | G44: =(F11*(1+0.035)/(0.105-0.035))/((1+0.105)^5)+B27 -> 39586797
B45: =B44+0.005 -> 0.13375 | C45: =($F$11*(1+0.015)/($B$45-0.015))/((1+$B$45)^5)+$B$27 -> 23599714 | D45: =($F$11*(1+0.02)/($B$45-0.02))/((1+$B$45)^5)+$B$27 -> 24411519 | E45: =($F$11*(1+0.025)/($B$45-0.025))/((1+$B$45)^5)+$B$27 -> 25297974 | F45: =($F$11*(1+0.03)/($B$45-0.03))/((1+$B$45)^5)+$B$27 -> 26269869 | G45: =(F11*(1+0.035)/(0.11-0.035))/((1+0.11)^5)+B27 -> 36741215
B46: =B45+0.005 -> 0.13875 | C46: =($F$11*(1+0.015)/($B$46-0.015))/((1+$B$46)^5)+$B$27 -> 22586389 | D46: =($F$11*(1+0.02)/($B$46-0.02))/((1+$B$46)^5)+$B$27 -> 23319575 | E46: =($F$11*(1+0.025)/($B$46-0.025))/((1+$B$46)^5)+$B$27 -> 24117216 | F46: =($F$11*(1+0.03)/($B$46-0.03))/((1+$B$46)^5)+$B$27 -> 24988204 | G46: =(F11*(1+0.035)/(0.115-0.035))/((1+0.115)^5)+B27 -> 34268268
B51: SENSITIVITY ANALYSIS: EQUITY VALUE (€M)
B52: Terminal Growth Rate (g) vs WACC
B54: WACC ↓ / g → | C54: 1.5% | D54: 2.0% | E54: 2.5% | F54: 3.0% | G54: 3.5%
B55: =B56-0.005 -> 0.10875 | C55: =($F$11*(1+0.015)/($B$55-0.015))/((1+$B$55)^5)+$B$27-$B$31+$B$32 -> 34014908 | D55: =($F$11*(1+0.02)/($B$55-0.02))/((1+$B$55)^5)+$B$27-$B$31+$B$32 -> 35455802 | E55: =($F$11*(1+0.025)/($B$55-0.025))/((1+$B$55)^5)+$B$27-$B$31+$B$32 -> 37068743 | F55: =($F$11*(1+0.03)/($B$55-0.03))/((1+$B$55)^5)+$B$27-$B$31+$B$32 -> 38886502 | G55: =(F11*(1+0.035)/(0.085-0.035))/((1+0.085)^5)+B27-B31+B32 -> 60485208
B56: =B57-0.005 -> 0.11375 | C56: =($F$11*(1+0.015)/($B$56-0.015))/((1+$B$56)^5)+$B$27-$B$31+$B$32 -> 32334942 | D56: =($F$11*(1+0.02)/($B$56-0.02))/((1+$B$56)^5)+$B$27-$B$31+$B$32 -> 33606825 | E56: =($F$11*(1+0.025)/($B$56-0.025))/((1+$B$56)^5)+$B$27-$B$31+$B$32 -> 35022018 | F56: =($F$11*(1+0.03)/($B$56-0.03))/((1+$B$56)^5)+$B$27-$B$31+$B$32 -> 36606190 | G56: =(F11*(1+0.035)/(0.09-0.035))/((1+0.09)^5)+B27-B31+B32 -> 54919724
...

Sheet LBO(No presentar)
A1: LBO ANALYSIS - UNIVERSIDAD DE MONDRAGÓN
A4: TRANSACTION ASSUMPTIONS | I4: KEY RISKS & MITIGANTS
A6: Entry Year | B6: 2025 | I6: Risk | J6: Mitigation | K6: Probability
A7: Exit Year | B7: 2029 | I7: Margin expansion slower than projected | J7: Conservative 5-year timeline; sector benchmarks well-established | K7: Medium
I8: Revenue growth below forecast | J8: 8% CAGR is conservative; multiple growth vectors (online, intl, B2B) | K8: Low
A9: Entry Valuation | I9: Resistance from cooperative stakeholders | J9: Management buy-in secured; clear value proposition for all parties | K9: Medium
A10: EBITDA (FY 2025E) | B10: =IS!C17 -> 1303248.6 | I10: Regulatory hurdles in privatization | J10: Precedent exists in Spanish education sector; legal DD completed | K10: Low
A11: Entry EV / EBITDA Multiple | B11: 12 | I11: Competition intensifies | J11: Strong regional brand; differentiated model with cooperative heritage | K11: Medium
A12: Enterprise Value (Entry) | B12: =B10*B11 -> 15638983
A14: Purchase Price | B14: =B12 -> 15638983
A15: Transaction Fees (%) | B15: 0.03
A16: Transaction Fees (€) | B16: =B14*B15 -> 469169.49
A17: Total Uses | B17: =B14+B16 -> 16108152
A19: FINANCING STRUCTURE
A21: Debt (% of Total Uses) | B21: 0.6
A22: Equity (% of Total Uses) | B22: 0.4
A24: Debt Financing (€) | B24: =B17*B21 -> 9664891.5
A25: Equity Financing (€) | B25: =B17*B22 -> 6443261
A26: Total Sources | B26: =B24+B25 -> 16108152
A28: Check (Should be 0) | B28: =B26-B17 -> 0
A30: DEBT ASSUMPTIONS
A32: Interest Rate (annual) | B32: 0.065 | D32: Coste de la deuda: Vincularlo a la salud financiera de la compañía y a las condiciones actuales de mercado
A33: Repayment Strategy | B33: Cash Sweep
A34: Minimum Cash (€) | B34: 500000
A37: DEBT SCHEDULE
B38: FY 2024 | C38: FY 2025 | D38: FY 2026 | E38: FY 2027 | F38: FY 2028 | G38: FY 2029
A39: Beginning Balance | B39: 0 | C39: =B24 -> 9664891.5 | D39: =C43 -> 9089924.6 | E39: =D43 -> 7410442.4 | F39: =E43 -> 4926196.2 | G39: =F43 -> 1606750.4
A40: (+) Drawdowns | B40: 0 | C40: 0 | D40: 0 | E40: 0 | F40: 0 | G40: 0
A41: (-) Mandatory Repayment | B41: 0 | C41: 0 | D41: 0 | E41: 0 | F41: 0 | G41: 0
A42: (-) Cash Sweep | B42: 0 | C42: =MAX(0,MIN(C39,CF!B10-C44-$B$34)) -> 574966.85 | D42: =MAX(0,MIN(D39,CF!C10-D44-$B$34)) -> 1679482.2 | E42: =MAX(0,MIN(E39,CF!D10-E44-$B$34)) -> 2484246.2 | F42: =MAX(0,MIN(F39,CF!E10-F44-$B$34)) -> 3319445.8 | G42: =MAX(0,MIN(G39,CF!F10-G44-$B$34)) -> 1606750.4
A43: Ending Balance | B43: =B39+B40-B41-B42 -> 0 | C43: =C39+C40-C41-C42 -> 9089924.6 | D43: =D39+D40-D41-D42 -> 7410442.4 | E43: =E39+E40-E41-E42 -> 4926196.2 | F43: =F39+F40-F41-F42 -> 1606750.4 | G43: =G39+G40-G41-G42 -> 0
A45: Interest Expense | B45: 0 | C45: =C39*$B$32 -> 628217.94 | D45: =D39*$B$32 -> 590845.1 | E45: =E39*$B$32 -> 481678.76 | F45: =F39*$B$32 -> 320202.75 | G45: =G39*$B$32 -> 104438.77
A46: Debt / EBITDA | B46: 0 | C46: =IF(IS!C17>0,C43/IS!C17,0) -> 6.9748203 | D46: =IF(IS!D17>0,D43/IS!D17,0) -> 3.0292533 | E46: =IF(IS!E17>0,E43/IS!E17,0) -> 1.3886656 | F46: =IF(IS!F17>0,F43/IS!F17,0) -> 0.35659098 | G46: =IF(IS!G17>0,G43/IS!G17,0) -> 0
A49: EXIT & RETURNS
A51: Exit EBITDA (FY 2029) | B51: =IS!G17 -> 5256712.9
A52: Exit EV / EBITDA Multiple | B52: 8
A53: Exit Enterprise Value | B53: =B51*B52 -> 42053703
A54: (-) Net Debt at Exit | B54: =G43 -> 0
A55: Exit Equity Value | B55: =B53-B54 -> 42053703
A57: Initial Equity Investment | B57: =B25 -> 6443261
...
